<?xml version="1.0" ?>
<!-- =================================================================================== -->
<!-- |    This document was autogenerated by xacro from snake.xacro                    | -->
<!-- |    EDITING THIS FILE BY HAND IS NOT RECOMMENDED                                 | -->
<!-- =================================================================================== -->
<robot name="snake" xmlns:xacro="http://www.ros.org/wiki/xacro">
  <!-- snake properties -->
  <!-- 1=simple_joint -1=springy_joint -->
  <!-- Spring joints are joints with a center springy link-->
  <!-- Spring joint revolute -->
  <!-- Simple joints are simple, lightly damped and frictioned joints-->
  <link name="module_5">
    <collision>
      <geometry>
        <cylinder length="0.5" radius="0.025"/>
      </geometry>
      <origin rpy="0 0 0" xyz="0 0 -0.25"/>
    </collision>
    <visual>
      <geometry>
        <cylinder length="0.5" radius="0.025"/>
      </geometry>
      <origin rpy="0 0 0" xyz="0 0 -0.25"/>
    </visual>
    <inertial>
      <origin rpy="0 0 0" xyz="0 0 -0.25"/>
      <mass value="0.159"/>
      <inertia ixx="0.00006" ixy="0" ixz="0" iyy="0.00006" iyz="0" izz="0.00006"/>
    </inertial>
  </link>
  <!-- Simple joint -->
  <joint name="joint_5_4.0" type="revolute">
    <limit effort="1000.0" lower="-1.57075" upper="1.57075" velocity="10"/>
    <dynamics damping="0.001" friction="0.2"/>
    <parent link="module_5"/>
    <child link="module_4.0"/>
    <origin xyz="0 0 -0.5"/>
    <axis xyz="0 1 0"/>
  </joint>
  <link name="module_4.0">
    <collision>
      <geometry>
        <cylinder length="0.5" radius="0.025"/>
      </geometry>
      <origin rpy="0 0 0" xyz="0 0 -0.25"/>
    </collision>
    <visual>
      <geometry>
        <cylinder length="0.5" radius="0.025"/>
      </geometry>
      <origin rpy="0 0 0" xyz="0 0 -0.25"/>
    </visual>
    <inertial>
      <origin rpy="0 0 0" xyz="0 0 -0.25"/>
      <mass value="0.159"/>
      <inertia ixx="0.00006" ixy="0" ixz="0" iyy="0.00006" iyz="0" izz="0.00006"/>
    </inertial>
  </link>
  <!-- Simple joint -->
  <joint name="joint_4.0_3.0" type="revolute">
    <limit effort="1000.0" lower="-1.57075" upper="1.57075" velocity="10"/>
    <dynamics damping="0.001" friction="0.2"/>
    <parent link="module_4.0"/>
    <child link="module_3.0"/>
    <origin xyz="0 0 -0.5"/>
    <axis xyz="1 0 0"/>
  </joint>
  <link name="module_3.0">
    <collision>
      <geometry>
        <cylinder length="0.5" radius="0.025"/>
      </geometry>
      <origin rpy="0 0 0" xyz="0 0 -0.25"/>
    </collision>
    <visual>
      <geometry>
        <cylinder length="0.5" radius="0.025"/>
      </geometry>
      <origin rpy="0 0 0" xyz="0 0 -0.25"/>
    </visual>
    <inertial>
      <origin rpy="0 0 0" xyz="0 0 -0.25"/>
      <mass value="0.159"/>
      <inertia ixx="0.00006" ixy="0" ixz="0" iyy="0.00006" iyz="0" izz="0.00006"/>
    </inertial>
  </link>
  <!-- Simple joint -->
  <joint name="joint_3.0_2.0" type="revolute">
    <limit effort="1000.0" lower="-1.57075" upper="1.57075" velocity="10"/>
    <dynamics damping="0.001" friction="0.2"/>
    <parent link="module_3.0"/>
    <child link="module_2.0"/>
    <origin xyz="0 0 -0.5"/>
    <axis xyz="0 1 0"/>
  </joint>
  <link name="module_2.0">
    <collision>
      <geometry>
        <cylinder length="0.5" radius="0.025"/>
      </geometry>
      <origin rpy="0 0 0" xyz="0 0 -0.25"/>
    </collision>
    <visual>
      <geometry>
        <cylinder length="0.5" radius="0.025"/>
      </geometry>
      <origin rpy="0 0 0" xyz="0 0 -0.25"/>
    </visual>
    <inertial>
      <origin rpy="0 0 0" xyz="0 0 -0.25"/>
      <mass value="0.159"/>
      <inertia ixx="0.00006" ixy="0" ixz="0" iyy="0.00006" iyz="0" izz="0.00006"/>
    </inertial>
  </link>
  <!-- Simple joint -->
  <joint name="joint_2.0_1.0" type="revolute">
    <limit effort="1000.0" lower="-1.57075" upper="1.57075" velocity="10"/>
    <dynamics damping="0.001" friction="0.2"/>
    <parent link="module_2.0"/>
    <child link="module_1.0"/>
    <origin xyz="0 0 -0.5"/>
    <axis xyz="1 0 0"/>
  </joint>
  <link name="module_1.0">
    <collision>
      <geometry>
        <cylinder length="0.5" radius="0.025"/>
      </geometry>
      <origin rpy="0 0 0" xyz="0 0 -0.25"/>
    </collision>
    <visual>
      <geometry>
        <cylinder length="0.5" radius="0.025"/>
      </geometry>
      <origin rpy="0 0 0" xyz="0 0 -0.25"/>
    </visual>
    <inertial>
      <origin rpy="0 0 0" xyz="0 0 -0.25"/>
      <mass value="0.159"/>
      <inertia ixx="0.00006" ixy="0" ixz="0" iyy="0.00006" iyz="0" izz="0.00006"/>
    </inertial>
  </link>
  <!-- Simple joint -->
  <joint name="joint_1.0_0.0" type="revolute">
    <limit effort="1000.0" lower="-1.57075" upper="1.57075" velocity="10"/>
    <dynamics damping="0.001" friction="0.2"/>
    <parent link="module_1.0"/>
    <child link="module_0.0"/>
    <origin xyz="0 0 -0.5"/>
    <axis xyz="0 1 0"/>
  </joint>
  <link name="module_0.0">
    <collision>
      <geometry>
        <cylinder length="0.5" radius="0.025"/>
      </geometry>
      <origin rpy="0 0 0" xyz="0 0 -0.25"/>
    </collision>
    <visual>
      <geometry>
        <cylinder length="0.5" radius="0.025"/>
      </geometry>
      <origin rpy="0 0 0" xyz="0 0 -0.25"/>
    </visual>
    <inertial>
      <origin rpy="0 0 0" xyz="0 0 -0.25"/>
      <mass value="0.159"/>
      <inertia ixx="0.00006" ixy="0" ixz="0" iyy="0.00006" iyz="0" izz="0.00006"/>
    </inertial>
  </link>
  <!-- Simple joint -->
  <joint name="joint_0.0_-1.0" type="revolute">
    <limit effort="1000.0" lower="-1.57075" upper="1.57075" velocity="10"/>
    <dynamics damping="0.001" friction="0.2"/>
    <parent link="module_0.0"/>
    <child link="module_-1.0"/>
    <origin xyz="0 0 -0.5"/>
    <axis xyz="1 0 0"/>
  </joint>
  <link name="module_-1.0">
    <collision>
      <geometry>
        <cylinder length="0.5" radius="0.025"/>
      </geometry>
      <origin rpy="0 0 0" xyz="0 0 -0.25"/>
    </collision>
    <visual>
      <geometry>
        <cylinder length="0.5" radius="0.025"/>
      </geometry>
      <origin rpy="0 0 0" xyz="0 0 -0.25"/>
    </visual>
    <inertial>
      <origin rpy="0 0 0" xyz="0 0 -0.25"/>
      <mass value="0.159"/>
      <inertia ixx="0.00006" ixy="0" ixz="0" iyy="0.00006" iyz="0" izz="0.00006"/>
    </inertial>
  </link>
</robot>

