<?xml version="1.0" ?>
<!-- =================================================================================== -->
<!-- |    This document was autogenerated by xacro from snake.xacro                    | -->
<!-- |    EDITING THIS FILE BY HAND IS NOT RECOMMENDED                                 | -->
<!-- =================================================================================== -->
<robot name="snake" xmlns:xacro="http://www.ros.org/wiki/xacro">
  <!-- snake properties -->
  <!-- 1=simple_joint -1=springy_joint -->
  <!-- Spring joints are joints with a center springy link-->
  <!-- Simple joints are simple, lightly damped and frictioned joints-->
  <link name="link_8">
    <collision>
      <geometry>
        <cylinder length="0.2" radius="0.025"/>
      </geometry>
      <origin rpy="0 1.57075 0" xyz="-0.1 0 0"/>
    </collision>
    <visual>
      <geometry>
        <cylinder length="0.2" radius="0.025"/>
      </geometry>
      <origin rpy="0 1.57075 0" xyz="-0.1 0 0"/>
    </visual>
    <inertial>
      <origin rpy="0 0 0" xyz="-0.1 0 0"/>
      <mass value="0.2"/>
      <inertia ixx="0.00006" ixy="0" ixz="0" iyy="0.00006" iyz="0" izz="0.00006"/>
    </inertial>
  </link>
  <!-- Springy joint -->
  <joint name="joint_8_m" type="revolute">
    <limit effort="1000.0" lower="-1.57075" upper="1.57075" velocity="10"/>
    <dynamics damping="0.001" friction="0.2"/>
    <parent link="link_8"/>
    <child link="spring_8"/>
    <origin xyz="-0.2 0 0"/>
    <axis xyz="0 1 0"/>
  </joint>
  <link name="spring_8">
    <visual>
      <geometry>
        <cylinder length="0.05" radius="0.001"/>
      </geometry>
      <origin rpy="3.1415 0 0" xyz="0 0 0"/>
    </visual>
    <inertial>
      <mass value="0.01"/>
      <inertia ixx="6e-06" ixy="0.0" ixz="0.0" iyy="6e-06" iyz="0.0" izz="6e-06"/>
    </inertial>
  </link>
  <joint name="joint_8_7.0" type="revolute">
    <limit effort="1000.0" lower="-1.57075" upper="1.57075" velocity="10"/>
    <dynamics damping="0.001" friction="0.2"/>
    <parent link="spring_8"/>
    <child link="link_7.0"/>
    <origin rpy="0 0 0" xyz="0 0 0"/>
    <axis xyz="0 1 0"/>
  </joint>
  <link name="link_7.0">
    <collision>
      <geometry>
        <cylinder length="0.2" radius="0.025"/>
      </geometry>
      <origin rpy="0 1.57075 0" xyz="-0.1 0 0"/>
    </collision>
    <visual>
      <geometry>
        <cylinder length="0.2" radius="0.025"/>
      </geometry>
      <origin rpy="0 1.57075 0" xyz="-0.1 0 0"/>
    </visual>
    <inertial>
      <origin rpy="0 0 0" xyz="-0.1 0 0"/>
      <mass value="0.2"/>
      <inertia ixx="0.00006" ixy="0" ixz="0" iyy="0.00006" iyz="0" izz="0.00006"/>
    </inertial>
  </link>
  <!-- Springy joint -->
  <joint name="joint_7.0_m" type="revolute">
    <limit effort="1000.0" lower="-1.57075" upper="1.57075" velocity="10"/>
    <dynamics damping="0.001" friction="0.2"/>
    <parent link="link_7.0"/>
    <child link="spring_7.0"/>
    <origin xyz="-0.2 0 0"/>
    <axis xyz="1 0 0"/>
  </joint>
  <link name="spring_7.0">
    <visual>
      <geometry>
        <cylinder length="0.05" radius="0.001"/>
      </geometry>
      <origin rpy="3.1415 0 0" xyz="0 0 0"/>
    </visual>
    <inertial>
      <mass value="0.01"/>
      <inertia ixx="6e-06" ixy="0.0" ixz="0.0" iyy="6e-06" iyz="0.0" izz="6e-06"/>
    </inertial>
  </link>
  <joint name="joint_7.0_6.0" type="revolute">
    <limit effort="1000.0" lower="-1.57075" upper="1.57075" velocity="10"/>
    <dynamics damping="0.001" friction="0.2"/>
    <parent link="spring_7.0"/>
    <child link="link_6.0"/>
    <origin rpy="0 0 0" xyz="0 0 0"/>
    <axis xyz="1 0 0"/>
  </joint>
  <link name="link_6.0">
    <collision>
      <geometry>
        <cylinder length="0.2" radius="0.025"/>
      </geometry>
      <origin rpy="0 1.57075 0" xyz="-0.1 0 0"/>
    </collision>
    <visual>
      <geometry>
        <cylinder length="0.2" radius="0.025"/>
      </geometry>
      <origin rpy="0 1.57075 0" xyz="-0.1 0 0"/>
    </visual>
    <inertial>
      <origin rpy="0 0 0" xyz="-0.1 0 0"/>
      <mass value="0.2"/>
      <inertia ixx="0.00006" ixy="0" ixz="0" iyy="0.00006" iyz="0" izz="0.00006"/>
    </inertial>
  </link>
  <!-- Springy joint -->
  <joint name="joint_6.0_m" type="revolute">
    <limit effort="1000.0" lower="-1.57075" upper="1.57075" velocity="10"/>
    <dynamics damping="0.001" friction="0.2"/>
    <parent link="link_6.0"/>
    <child link="spring_6.0"/>
    <origin xyz="-0.2 0 0"/>
    <axis xyz="0 1 0"/>
  </joint>
  <link name="spring_6.0">
    <visual>
      <geometry>
        <cylinder length="0.05" radius="0.001"/>
      </geometry>
      <origin rpy="3.1415 0 0" xyz="0 0 0"/>
    </visual>
    <inertial>
      <mass value="0.01"/>
      <inertia ixx="6e-06" ixy="0.0" ixz="0.0" iyy="6e-06" iyz="0.0" izz="6e-06"/>
    </inertial>
  </link>
  <joint name="joint_6.0_5.0" type="revolute">
    <limit effort="1000.0" lower="-1.57075" upper="1.57075" velocity="10"/>
    <dynamics damping="0.001" friction="0.2"/>
    <parent link="spring_6.0"/>
    <child link="link_5.0"/>
    <origin rpy="0 0 0" xyz="0 0 0"/>
    <axis xyz="0 1 0"/>
  </joint>
  <link name="link_5.0">
    <collision>
      <geometry>
        <cylinder length="0.2" radius="0.025"/>
      </geometry>
      <origin rpy="0 1.57075 0" xyz="-0.1 0 0"/>
    </collision>
    <visual>
      <geometry>
        <cylinder length="0.2" radius="0.025"/>
      </geometry>
      <origin rpy="0 1.57075 0" xyz="-0.1 0 0"/>
    </visual>
    <inertial>
      <origin rpy="0 0 0" xyz="-0.1 0 0"/>
      <mass value="0.2"/>
      <inertia ixx="0.00006" ixy="0" ixz="0" iyy="0.00006" iyz="0" izz="0.00006"/>
    </inertial>
  </link>
  <!-- Springy joint -->
  <joint name="joint_5.0_m" type="revolute">
    <limit effort="1000.0" lower="-1.57075" upper="1.57075" velocity="10"/>
    <dynamics damping="0.001" friction="0.2"/>
    <parent link="link_5.0"/>
    <child link="spring_5.0"/>
    <origin xyz="-0.2 0 0"/>
    <axis xyz="1 0 0"/>
  </joint>
  <link name="spring_5.0">
    <visual>
      <geometry>
        <cylinder length="0.05" radius="0.001"/>
      </geometry>
      <origin rpy="3.1415 0 0" xyz="0 0 0"/>
    </visual>
    <inertial>
      <mass value="0.01"/>
      <inertia ixx="6e-06" ixy="0.0" ixz="0.0" iyy="6e-06" iyz="0.0" izz="6e-06"/>
    </inertial>
  </link>
  <joint name="joint_5.0_4.0" type="revolute">
    <limit effort="1000.0" lower="-1.57075" upper="1.57075" velocity="10"/>
    <dynamics damping="0.001" friction="0.2"/>
    <parent link="spring_5.0"/>
    <child link="link_4.0"/>
    <origin rpy="0 0 0" xyz="0 0 0"/>
    <axis xyz="1 0 0"/>
  </joint>
  <link name="link_4.0">
    <collision>
      <geometry>
        <cylinder length="0.2" radius="0.025"/>
      </geometry>
      <origin rpy="0 1.57075 0" xyz="-0.1 0 0"/>
    </collision>
    <visual>
      <geometry>
        <cylinder length="0.2" radius="0.025"/>
      </geometry>
      <origin rpy="0 1.57075 0" xyz="-0.1 0 0"/>
    </visual>
    <inertial>
      <origin rpy="0 0 0" xyz="-0.1 0 0"/>
      <mass value="0.2"/>
      <inertia ixx="0.00006" ixy="0" ixz="0" iyy="0.00006" iyz="0" izz="0.00006"/>
    </inertial>
  </link>
  <!-- Springy joint -->
  <joint name="joint_4.0_m" type="revolute">
    <limit effort="1000.0" lower="-1.57075" upper="1.57075" velocity="10"/>
    <dynamics damping="0.001" friction="0.2"/>
    <parent link="link_4.0"/>
    <child link="spring_4.0"/>
    <origin xyz="-0.2 0 0"/>
    <axis xyz="0 1 0"/>
  </joint>
  <link name="spring_4.0">
    <visual>
      <geometry>
        <cylinder length="0.05" radius="0.001"/>
      </geometry>
      <origin rpy="3.1415 0 0" xyz="0 0 0"/>
    </visual>
    <inertial>
      <mass value="0.01"/>
      <inertia ixx="6e-06" ixy="0.0" ixz="0.0" iyy="6e-06" iyz="0.0" izz="6e-06"/>
    </inertial>
  </link>
  <joint name="joint_4.0_3.0" type="revolute">
    <limit effort="1000.0" lower="-1.57075" upper="1.57075" velocity="10"/>
    <dynamics damping="0.001" friction="0.2"/>
    <parent link="spring_4.0"/>
    <child link="link_3.0"/>
    <origin rpy="0 0 0" xyz="0 0 0"/>
    <axis xyz="0 1 0"/>
  </joint>
  <link name="link_3.0">
    <collision>
      <geometry>
        <cylinder length="0.2" radius="0.025"/>
      </geometry>
      <origin rpy="0 1.57075 0" xyz="-0.1 0 0"/>
    </collision>
    <visual>
      <geometry>
        <cylinder length="0.2" radius="0.025"/>
      </geometry>
      <origin rpy="0 1.57075 0" xyz="-0.1 0 0"/>
    </visual>
    <inertial>
      <origin rpy="0 0 0" xyz="-0.1 0 0"/>
      <mass value="0.2"/>
      <inertia ixx="0.00006" ixy="0" ixz="0" iyy="0.00006" iyz="0" izz="0.00006"/>
    </inertial>
  </link>
  <!-- Springy joint -->
  <joint name="joint_3.0_m" type="revolute">
    <limit effort="1000.0" lower="-1.57075" upper="1.57075" velocity="10"/>
    <dynamics damping="0.001" friction="0.2"/>
    <parent link="link_3.0"/>
    <child link="spring_3.0"/>
    <origin xyz="-0.2 0 0"/>
    <axis xyz="1 0 0"/>
  </joint>
  <link name="spring_3.0">
    <visual>
      <geometry>
        <cylinder length="0.05" radius="0.001"/>
      </geometry>
      <origin rpy="3.1415 0 0" xyz="0 0 0"/>
    </visual>
    <inertial>
      <mass value="0.01"/>
      <inertia ixx="6e-06" ixy="0.0" ixz="0.0" iyy="6e-06" iyz="0.0" izz="6e-06"/>
    </inertial>
  </link>
  <joint name="joint_3.0_2.0" type="revolute">
    <limit effort="1000.0" lower="-1.57075" upper="1.57075" velocity="10"/>
    <dynamics damping="0.001" friction="0.2"/>
    <parent link="spring_3.0"/>
    <child link="link_2.0"/>
    <origin rpy="0 0 0" xyz="0 0 0"/>
    <axis xyz="1 0 0"/>
  </joint>
  <link name="link_2.0">
    <collision>
      <geometry>
        <cylinder length="0.2" radius="0.025"/>
      </geometry>
      <origin rpy="0 1.57075 0" xyz="-0.1 0 0"/>
    </collision>
    <visual>
      <geometry>
        <cylinder length="0.2" radius="0.025"/>
      </geometry>
      <origin rpy="0 1.57075 0" xyz="-0.1 0 0"/>
    </visual>
    <inertial>
      <origin rpy="0 0 0" xyz="-0.1 0 0"/>
      <mass value="0.2"/>
      <inertia ixx="0.00006" ixy="0" ixz="0" iyy="0.00006" iyz="0" izz="0.00006"/>
    </inertial>
  </link>
  <!-- Springy joint -->
  <joint name="joint_2.0_m" type="revolute">
    <limit effort="1000.0" lower="-1.57075" upper="1.57075" velocity="10"/>
    <dynamics damping="0.001" friction="0.2"/>
    <parent link="link_2.0"/>
    <child link="spring_2.0"/>
    <origin xyz="-0.2 0 0"/>
    <axis xyz="0 1 0"/>
  </joint>
  <link name="spring_2.0">
    <visual>
      <geometry>
        <cylinder length="0.05" radius="0.001"/>
      </geometry>
      <origin rpy="3.1415 0 0" xyz="0 0 0"/>
    </visual>
    <inertial>
      <mass value="0.01"/>
      <inertia ixx="6e-06" ixy="0.0" ixz="0.0" iyy="6e-06" iyz="0.0" izz="6e-06"/>
    </inertial>
  </link>
  <joint name="joint_2.0_1.0" type="revolute">
    <limit effort="1000.0" lower="-1.57075" upper="1.57075" velocity="10"/>
    <dynamics damping="0.001" friction="0.2"/>
    <parent link="spring_2.0"/>
    <child link="link_1.0"/>
    <origin rpy="0 0 0" xyz="0 0 0"/>
    <axis xyz="0 1 0"/>
  </joint>
  <link name="link_1.0">
    <collision>
      <geometry>
        <cylinder length="0.2" radius="0.025"/>
      </geometry>
      <origin rpy="0 1.57075 0" xyz="-0.1 0 0"/>
    </collision>
    <visual>
      <geometry>
        <cylinder length="0.2" radius="0.025"/>
      </geometry>
      <origin rpy="0 1.57075 0" xyz="-0.1 0 0"/>
    </visual>
    <inertial>
      <origin rpy="0 0 0" xyz="-0.1 0 0"/>
      <mass value="0.2"/>
      <inertia ixx="0.00006" ixy="0" ixz="0" iyy="0.00006" iyz="0" izz="0.00006"/>
    </inertial>
  </link>
  <!-- Springy joint -->
  <joint name="joint_1.0_m" type="revolute">
    <limit effort="1000.0" lower="-1.57075" upper="1.57075" velocity="10"/>
    <dynamics damping="0.001" friction="0.2"/>
    <parent link="link_1.0"/>
    <child link="spring_1.0"/>
    <origin xyz="-0.2 0 0"/>
    <axis xyz="1 0 0"/>
  </joint>
  <link name="spring_1.0">
    <visual>
      <geometry>
        <cylinder length="0.05" radius="0.001"/>
      </geometry>
      <origin rpy="3.1415 0 0" xyz="0 0 0"/>
    </visual>
    <inertial>
      <mass value="0.01"/>
      <inertia ixx="6e-06" ixy="0.0" ixz="0.0" iyy="6e-06" iyz="0.0" izz="6e-06"/>
    </inertial>
  </link>
  <joint name="joint_1.0_0.0" type="revolute">
    <limit effort="1000.0" lower="-1.57075" upper="1.57075" velocity="10"/>
    <dynamics damping="0.001" friction="0.2"/>
    <parent link="spring_1.0"/>
    <child link="link_0.0"/>
    <origin rpy="0 0 0" xyz="0 0 0"/>
    <axis xyz="1 0 0"/>
  </joint>
  <link name="link_0.0">
    <collision>
      <geometry>
        <cylinder length="0.2" radius="0.025"/>
      </geometry>
      <origin rpy="0 1.57075 0" xyz="-0.1 0 0"/>
    </collision>
    <visual>
      <geometry>
        <cylinder length="0.2" radius="0.025"/>
      </geometry>
      <origin rpy="0 1.57075 0" xyz="-0.1 0 0"/>
    </visual>
    <inertial>
      <origin rpy="0 0 0" xyz="-0.1 0 0"/>
      <mass value="0.2"/>
      <inertia ixx="0.00006" ixy="0" ixz="0" iyy="0.00006" iyz="0" izz="0.00006"/>
    </inertial>
  </link>
  <!-- Springy joint -->
  <joint name="joint_0.0_m" type="revolute">
    <limit effort="1000.0" lower="-1.57075" upper="1.57075" velocity="10"/>
    <dynamics damping="0.001" friction="0.2"/>
    <parent link="link_0.0"/>
    <child link="spring_0.0"/>
    <origin xyz="-0.2 0 0"/>
    <axis xyz="0 1 0"/>
  </joint>
  <link name="spring_0.0">
    <visual>
      <geometry>
        <cylinder length="0.05" radius="0.001"/>
      </geometry>
      <origin rpy="3.1415 0 0" xyz="0 0 0"/>
    </visual>
    <inertial>
      <mass value="0.01"/>
      <inertia ixx="6e-06" ixy="0.0" ixz="0.0" iyy="6e-06" iyz="0.0" izz="6e-06"/>
    </inertial>
  </link>
  <joint name="joint_0.0_-1.0" type="revolute">
    <limit effort="1000.0" lower="-1.57075" upper="1.57075" velocity="10"/>
    <dynamics damping="0.001" friction="0.2"/>
    <parent link="spring_0.0"/>
    <child link="link_-1.0"/>
    <origin rpy="0 0 0" xyz="0 0 0"/>
    <axis xyz="0 1 0"/>
  </joint>
  <link name="link_-1.0">
    <collision>
      <geometry>
        <cylinder length="0.2" radius="0.025"/>
      </geometry>
      <origin rpy="0 1.57075 0" xyz="-0.1 0 0"/>
    </collision>
    <visual>
      <geometry>
        <cylinder length="0.2" radius="0.025"/>
      </geometry>
      <origin rpy="0 1.57075 0" xyz="-0.1 0 0"/>
    </visual>
    <inertial>
      <origin rpy="0 0 0" xyz="-0.1 0 0"/>
      <mass value="0.2"/>
      <inertia ixx="0.00006" ixy="0" ixz="0" iyy="0.00006" iyz="0" izz="0.00006"/>
    </inertial>
  </link>
</robot>

