<?xml version="1.0" ?>
<!-- =================================================================================== -->
<!-- |    This document was autogenerated by xacro from snake.xacro                    | -->
<!-- |    EDITING THIS FILE BY HAND IS NOT RECOMMENDED                                 | -->
<!-- =================================================================================== -->
<robot name="snake" xmlns:xacro="http://www.ros.org/wiki/xacro">
  <!-- snake properties -->
  <!-- 1=simple_joint -1=springy_joint -->
  <!-- Spring joints are joints with a center springy link-->
  <!-- Spring joint revolute -->
  <!-- Spring joint spherical -->
  <!-- Simple joints are simple, lightly damped and frictioned joints-->
  <!--  -->
  <!-- Simple joint spherical -->
  <link name="module_15">
    <collision>
      <geometry>
        <cylinder length="0.05" radius="0.025"/>
      </geometry>
      <origin rpy="0 0 0" xyz="0 0 -0.025"/>
    </collision>
    <visual>
      <geometry>
        <cylinder length="0.05" radius="0.025"/>
      </geometry>
      <origin rpy="0 0 0" xyz="0 0 -0.025"/>
    </visual>
    <inertial>
      <origin rpy="0 0 0" xyz="0 0 -0.025"/>
      <mass value="0.159"/>
      <inertia ixx="0.00006" ixy="0" ixz="0" iyy="0.00006" iyz="0" izz="0.00006"/>
    </inertial>
  </link>
  <!-- Springy joint -->
  <joint name="joint_15_m" type="revolute">
    <limit effort="1000.0" lower="-1.57075" upper="1.57075" velocity="10"/>
    <dynamics damping="0.001" friction="0.2"/>
    <parent link="module_15"/>
    <child link="spring_15"/>
    <origin xyz="0 0 -0.05"/>
    <axis xyz="0 1 0"/>
  </joint>
  <link name="spring_15">
    <visual>
      <geometry>
        <cylinder length="0.05" radius=".001"/>
      </geometry>
      <origin rpy="1.57075 0 0" xyz="0 0 0"/>
    </visual>
    <inertial>
      <mass value="0.001"/>
      <inertia ixx="0.0" ixy="0.0" ixz="0.0" iyy="0.0" iyz="0.0" izz="0.0"/>
    </inertial>
  </link>
  <joint name="joint_15_14.0" type="revolute">
    <limit effort="1000.0" lower="-1.57075" upper="1.57075" velocity="10"/>
    <!-- <dynamics damping="${damping}" friction="${friction}" /> -->
    <parent link="spring_15"/>
    <child link="module_14.0"/>
    <origin rpy="0 0 0" xyz="0 0 0"/>
    <axis xyz="0 1 0"/>
  </joint>
  <link name="module_14.0">
    <collision>
      <geometry>
        <cylinder length="0.05" radius="0.025"/>
      </geometry>
      <origin rpy="0 0 0" xyz="0 0 -0.025"/>
    </collision>
    <visual>
      <geometry>
        <cylinder length="0.05" radius="0.025"/>
      </geometry>
      <origin rpy="0 0 0" xyz="0 0 -0.025"/>
    </visual>
    <inertial>
      <origin rpy="0 0 0" xyz="0 0 -0.025"/>
      <mass value="0.159"/>
      <inertia ixx="0.00006" ixy="0" ixz="0" iyy="0.00006" iyz="0" izz="0.00006"/>
    </inertial>
  </link>
  <!-- Springy joint -->
  <joint name="joint_14.0_m" type="revolute">
    <limit effort="1000.0" lower="-1.57075" upper="1.57075" velocity="10"/>
    <dynamics damping="0.001" friction="0.2"/>
    <parent link="module_14.0"/>
    <child link="spring_14.0"/>
    <origin xyz="0 0 -0.05"/>
    <axis xyz="1 0 0"/>
  </joint>
  <link name="spring_14.0">
    <visual>
      <geometry>
        <cylinder length="0.05" radius=".001"/>
      </geometry>
      <origin rpy="1.57075 0 0" xyz="0 0 0"/>
    </visual>
    <inertial>
      <mass value="0.001"/>
      <inertia ixx="0.0" ixy="0.0" ixz="0.0" iyy="0.0" iyz="0.0" izz="0.0"/>
    </inertial>
  </link>
  <joint name="joint_14.0_13.0" type="revolute">
    <limit effort="1000.0" lower="-1.57075" upper="1.57075" velocity="10"/>
    <!-- <dynamics damping="${damping}" friction="${friction}" /> -->
    <parent link="spring_14.0"/>
    <child link="module_13.0"/>
    <origin rpy="0 0 0" xyz="0 0 0"/>
    <axis xyz="1 0 0"/>
  </joint>
  <link name="module_13.0">
    <collision>
      <geometry>
        <cylinder length="0.05" radius="0.025"/>
      </geometry>
      <origin rpy="0 0 0" xyz="0 0 -0.025"/>
    </collision>
    <visual>
      <geometry>
        <cylinder length="0.05" radius="0.025"/>
      </geometry>
      <origin rpy="0 0 0" xyz="0 0 -0.025"/>
    </visual>
    <inertial>
      <origin rpy="0 0 0" xyz="0 0 -0.025"/>
      <mass value="0.159"/>
      <inertia ixx="0.00006" ixy="0" ixz="0" iyy="0.00006" iyz="0" izz="0.00006"/>
    </inertial>
  </link>
  <!-- Springy joint -->
  <joint name="joint_13.0_m" type="revolute">
    <limit effort="1000.0" lower="-1.57075" upper="1.57075" velocity="10"/>
    <dynamics damping="0.001" friction="0.2"/>
    <parent link="module_13.0"/>
    <child link="spring_13.0"/>
    <origin xyz="0 0 -0.05"/>
    <axis xyz="0 1 0"/>
  </joint>
  <link name="spring_13.0">
    <visual>
      <geometry>
        <cylinder length="0.05" radius=".001"/>
      </geometry>
      <origin rpy="1.57075 0 0" xyz="0 0 0"/>
    </visual>
    <inertial>
      <mass value="0.001"/>
      <inertia ixx="0.0" ixy="0.0" ixz="0.0" iyy="0.0" iyz="0.0" izz="0.0"/>
    </inertial>
  </link>
  <joint name="joint_13.0_12.0" type="revolute">
    <limit effort="1000.0" lower="-1.57075" upper="1.57075" velocity="10"/>
    <!-- <dynamics damping="${damping}" friction="${friction}" /> -->
    <parent link="spring_13.0"/>
    <child link="module_12.0"/>
    <origin rpy="0 0 0" xyz="0 0 0"/>
    <axis xyz="0 1 0"/>
  </joint>
  <link name="module_12.0">
    <collision>
      <geometry>
        <cylinder length="0.05" radius="0.025"/>
      </geometry>
      <origin rpy="0 0 0" xyz="0 0 -0.025"/>
    </collision>
    <visual>
      <geometry>
        <cylinder length="0.05" radius="0.025"/>
      </geometry>
      <origin rpy="0 0 0" xyz="0 0 -0.025"/>
    </visual>
    <inertial>
      <origin rpy="0 0 0" xyz="0 0 -0.025"/>
      <mass value="0.159"/>
      <inertia ixx="0.00006" ixy="0" ixz="0" iyy="0.00006" iyz="0" izz="0.00006"/>
    </inertial>
  </link>
  <!-- Springy joint -->
  <joint name="joint_12.0_m" type="revolute">
    <limit effort="1000.0" lower="-1.57075" upper="1.57075" velocity="10"/>
    <dynamics damping="0.001" friction="0.2"/>
    <parent link="module_12.0"/>
    <child link="spring_12.0"/>
    <origin xyz="0 0 -0.05"/>
    <axis xyz="1 0 0"/>
  </joint>
  <link name="spring_12.0">
    <visual>
      <geometry>
        <cylinder length="0.05" radius=".001"/>
      </geometry>
      <origin rpy="1.57075 0 0" xyz="0 0 0"/>
    </visual>
    <inertial>
      <mass value="0.001"/>
      <inertia ixx="0.0" ixy="0.0" ixz="0.0" iyy="0.0" iyz="0.0" izz="0.0"/>
    </inertial>
  </link>
  <joint name="joint_12.0_11.0" type="revolute">
    <limit effort="1000.0" lower="-1.57075" upper="1.57075" velocity="10"/>
    <!-- <dynamics damping="${damping}" friction="${friction}" /> -->
    <parent link="spring_12.0"/>
    <child link="module_11.0"/>
    <origin rpy="0 0 0" xyz="0 0 0"/>
    <axis xyz="1 0 0"/>
  </joint>
  <link name="module_11.0">
    <collision>
      <geometry>
        <cylinder length="0.05" radius="0.025"/>
      </geometry>
      <origin rpy="0 0 0" xyz="0 0 -0.025"/>
    </collision>
    <visual>
      <geometry>
        <cylinder length="0.05" radius="0.025"/>
      </geometry>
      <origin rpy="0 0 0" xyz="0 0 -0.025"/>
    </visual>
    <inertial>
      <origin rpy="0 0 0" xyz="0 0 -0.025"/>
      <mass value="0.159"/>
      <inertia ixx="0.00006" ixy="0" ixz="0" iyy="0.00006" iyz="0" izz="0.00006"/>
    </inertial>
  </link>
  <!-- Springy joint -->
  <joint name="joint_11.0_m" type="revolute">
    <limit effort="1000.0" lower="-1.57075" upper="1.57075" velocity="10"/>
    <dynamics damping="0.001" friction="0.2"/>
    <parent link="module_11.0"/>
    <child link="spring_11.0"/>
    <origin xyz="0 0 -0.05"/>
    <axis xyz="0 1 0"/>
  </joint>
  <link name="spring_11.0">
    <visual>
      <geometry>
        <cylinder length="0.05" radius=".001"/>
      </geometry>
      <origin rpy="1.57075 0 0" xyz="0 0 0"/>
    </visual>
    <inertial>
      <mass value="0.001"/>
      <inertia ixx="0.0" ixy="0.0" ixz="0.0" iyy="0.0" iyz="0.0" izz="0.0"/>
    </inertial>
  </link>
  <joint name="joint_11.0_10.0" type="revolute">
    <limit effort="1000.0" lower="-1.57075" upper="1.57075" velocity="10"/>
    <!-- <dynamics damping="${damping}" friction="${friction}" /> -->
    <parent link="spring_11.0"/>
    <child link="module_10.0"/>
    <origin rpy="0 0 0" xyz="0 0 0"/>
    <axis xyz="0 1 0"/>
  </joint>
  <link name="module_10.0">
    <collision>
      <geometry>
        <cylinder length="0.05" radius="0.025"/>
      </geometry>
      <origin rpy="0 0 0" xyz="0 0 -0.025"/>
    </collision>
    <visual>
      <geometry>
        <cylinder length="0.05" radius="0.025"/>
      </geometry>
      <origin rpy="0 0 0" xyz="0 0 -0.025"/>
    </visual>
    <inertial>
      <origin rpy="0 0 0" xyz="0 0 -0.025"/>
      <mass value="0.159"/>
      <inertia ixx="0.00006" ixy="0" ixz="0" iyy="0.00006" iyz="0" izz="0.00006"/>
    </inertial>
  </link>
  <!-- Springy joint -->
  <joint name="joint_10.0_m" type="revolute">
    <limit effort="1000.0" lower="-1.57075" upper="1.57075" velocity="10"/>
    <dynamics damping="0.001" friction="0.2"/>
    <parent link="module_10.0"/>
    <child link="spring_10.0"/>
    <origin xyz="0 0 -0.05"/>
    <axis xyz="1 0 0"/>
  </joint>
  <link name="spring_10.0">
    <visual>
      <geometry>
        <cylinder length="0.05" radius=".001"/>
      </geometry>
      <origin rpy="1.57075 0 0" xyz="0 0 0"/>
    </visual>
    <inertial>
      <mass value="0.001"/>
      <inertia ixx="0.0" ixy="0.0" ixz="0.0" iyy="0.0" iyz="0.0" izz="0.0"/>
    </inertial>
  </link>
  <joint name="joint_10.0_9.0" type="revolute">
    <limit effort="1000.0" lower="-1.57075" upper="1.57075" velocity="10"/>
    <!-- <dynamics damping="${damping}" friction="${friction}" /> -->
    <parent link="spring_10.0"/>
    <child link="module_9.0"/>
    <origin rpy="0 0 0" xyz="0 0 0"/>
    <axis xyz="1 0 0"/>
  </joint>
  <link name="module_9.0">
    <collision>
      <geometry>
        <cylinder length="0.05" radius="0.025"/>
      </geometry>
      <origin rpy="0 0 0" xyz="0 0 -0.025"/>
    </collision>
    <visual>
      <geometry>
        <cylinder length="0.05" radius="0.025"/>
      </geometry>
      <origin rpy="0 0 0" xyz="0 0 -0.025"/>
    </visual>
    <inertial>
      <origin rpy="0 0 0" xyz="0 0 -0.025"/>
      <mass value="0.159"/>
      <inertia ixx="0.00006" ixy="0" ixz="0" iyy="0.00006" iyz="0" izz="0.00006"/>
    </inertial>
  </link>
  <!-- Springy joint -->
  <joint name="joint_9.0_m" type="revolute">
    <limit effort="1000.0" lower="-1.57075" upper="1.57075" velocity="10"/>
    <dynamics damping="0.001" friction="0.2"/>
    <parent link="module_9.0"/>
    <child link="spring_9.0"/>
    <origin xyz="0 0 -0.05"/>
    <axis xyz="0 1 0"/>
  </joint>
  <link name="spring_9.0">
    <visual>
      <geometry>
        <cylinder length="0.05" radius=".001"/>
      </geometry>
      <origin rpy="1.57075 0 0" xyz="0 0 0"/>
    </visual>
    <inertial>
      <mass value="0.001"/>
      <inertia ixx="0.0" ixy="0.0" ixz="0.0" iyy="0.0" iyz="0.0" izz="0.0"/>
    </inertial>
  </link>
  <joint name="joint_9.0_8.0" type="revolute">
    <limit effort="1000.0" lower="-1.57075" upper="1.57075" velocity="10"/>
    <!-- <dynamics damping="${damping}" friction="${friction}" /> -->
    <parent link="spring_9.0"/>
    <child link="module_8.0"/>
    <origin rpy="0 0 0" xyz="0 0 0"/>
    <axis xyz="0 1 0"/>
  </joint>
  <link name="module_8.0">
    <collision>
      <geometry>
        <cylinder length="0.05" radius="0.025"/>
      </geometry>
      <origin rpy="0 0 0" xyz="0 0 -0.025"/>
    </collision>
    <visual>
      <geometry>
        <cylinder length="0.05" radius="0.025"/>
      </geometry>
      <origin rpy="0 0 0" xyz="0 0 -0.025"/>
    </visual>
    <inertial>
      <origin rpy="0 0 0" xyz="0 0 -0.025"/>
      <mass value="0.159"/>
      <inertia ixx="0.00006" ixy="0" ixz="0" iyy="0.00006" iyz="0" izz="0.00006"/>
    </inertial>
  </link>
  <!-- Springy joint -->
  <joint name="joint_8.0_m" type="revolute">
    <limit effort="1000.0" lower="-1.57075" upper="1.57075" velocity="10"/>
    <dynamics damping="0.001" friction="0.2"/>
    <parent link="module_8.0"/>
    <child link="spring_8.0"/>
    <origin xyz="0 0 -0.05"/>
    <axis xyz="1 0 0"/>
  </joint>
  <link name="spring_8.0">
    <visual>
      <geometry>
        <cylinder length="0.05" radius=".001"/>
      </geometry>
      <origin rpy="1.57075 0 0" xyz="0 0 0"/>
    </visual>
    <inertial>
      <mass value="0.001"/>
      <inertia ixx="0.0" ixy="0.0" ixz="0.0" iyy="0.0" iyz="0.0" izz="0.0"/>
    </inertial>
  </link>
  <joint name="joint_8.0_7.0" type="revolute">
    <limit effort="1000.0" lower="-1.57075" upper="1.57075" velocity="10"/>
    <!-- <dynamics damping="${damping}" friction="${friction}" /> -->
    <parent link="spring_8.0"/>
    <child link="module_7.0"/>
    <origin rpy="0 0 0" xyz="0 0 0"/>
    <axis xyz="1 0 0"/>
  </joint>
  <link name="module_7.0">
    <collision>
      <geometry>
        <cylinder length="0.05" radius="0.025"/>
      </geometry>
      <origin rpy="0 0 0" xyz="0 0 -0.025"/>
    </collision>
    <visual>
      <geometry>
        <cylinder length="0.05" radius="0.025"/>
      </geometry>
      <origin rpy="0 0 0" xyz="0 0 -0.025"/>
    </visual>
    <inertial>
      <origin rpy="0 0 0" xyz="0 0 -0.025"/>
      <mass value="0.159"/>
      <inertia ixx="0.00006" ixy="0" ixz="0" iyy="0.00006" iyz="0" izz="0.00006"/>
    </inertial>
  </link>
  <!-- Springy joint -->
  <joint name="joint_7.0_m" type="revolute">
    <limit effort="1000.0" lower="-1.57075" upper="1.57075" velocity="10"/>
    <dynamics damping="0.001" friction="0.2"/>
    <parent link="module_7.0"/>
    <child link="spring_7.0"/>
    <origin xyz="0 0 -0.05"/>
    <axis xyz="0 1 0"/>
  </joint>
  <link name="spring_7.0">
    <visual>
      <geometry>
        <cylinder length="0.05" radius=".001"/>
      </geometry>
      <origin rpy="1.57075 0 0" xyz="0 0 0"/>
    </visual>
    <inertial>
      <mass value="0.001"/>
      <inertia ixx="0.0" ixy="0.0" ixz="0.0" iyy="0.0" iyz="0.0" izz="0.0"/>
    </inertial>
  </link>
  <joint name="joint_7.0_6.0" type="revolute">
    <limit effort="1000.0" lower="-1.57075" upper="1.57075" velocity="10"/>
    <!-- <dynamics damping="${damping}" friction="${friction}" /> -->
    <parent link="spring_7.0"/>
    <child link="module_6.0"/>
    <origin rpy="0 0 0" xyz="0 0 0"/>
    <axis xyz="0 1 0"/>
  </joint>
  <link name="module_6.0">
    <collision>
      <geometry>
        <cylinder length="0.05" radius="0.025"/>
      </geometry>
      <origin rpy="0 0 0" xyz="0 0 -0.025"/>
    </collision>
    <visual>
      <geometry>
        <cylinder length="0.05" radius="0.025"/>
      </geometry>
      <origin rpy="0 0 0" xyz="0 0 -0.025"/>
    </visual>
    <inertial>
      <origin rpy="0 0 0" xyz="0 0 -0.025"/>
      <mass value="0.159"/>
      <inertia ixx="0.00006" ixy="0" ixz="0" iyy="0.00006" iyz="0" izz="0.00006"/>
    </inertial>
  </link>
  <!-- Springy joint -->
  <joint name="joint_6.0_m" type="revolute">
    <limit effort="1000.0" lower="-1.57075" upper="1.57075" velocity="10"/>
    <dynamics damping="0.001" friction="0.2"/>
    <parent link="module_6.0"/>
    <child link="spring_6.0"/>
    <origin xyz="0 0 -0.05"/>
    <axis xyz="1 0 0"/>
  </joint>
  <link name="spring_6.0">
    <visual>
      <geometry>
        <cylinder length="0.05" radius=".001"/>
      </geometry>
      <origin rpy="1.57075 0 0" xyz="0 0 0"/>
    </visual>
    <inertial>
      <mass value="0.001"/>
      <inertia ixx="0.0" ixy="0.0" ixz="0.0" iyy="0.0" iyz="0.0" izz="0.0"/>
    </inertial>
  </link>
  <joint name="joint_6.0_5.0" type="revolute">
    <limit effort="1000.0" lower="-1.57075" upper="1.57075" velocity="10"/>
    <!-- <dynamics damping="${damping}" friction="${friction}" /> -->
    <parent link="spring_6.0"/>
    <child link="module_5.0"/>
    <origin rpy="0 0 0" xyz="0 0 0"/>
    <axis xyz="1 0 0"/>
  </joint>
  <link name="module_5.0">
    <collision>
      <geometry>
        <cylinder length="0.05" radius="0.025"/>
      </geometry>
      <origin rpy="0 0 0" xyz="0 0 -0.025"/>
    </collision>
    <visual>
      <geometry>
        <cylinder length="0.05" radius="0.025"/>
      </geometry>
      <origin rpy="0 0 0" xyz="0 0 -0.025"/>
    </visual>
    <inertial>
      <origin rpy="0 0 0" xyz="0 0 -0.025"/>
      <mass value="0.159"/>
      <inertia ixx="0.00006" ixy="0" ixz="0" iyy="0.00006" iyz="0" izz="0.00006"/>
    </inertial>
  </link>
  <!-- Springy joint -->
  <joint name="joint_5.0_m" type="revolute">
    <limit effort="1000.0" lower="-1.57075" upper="1.57075" velocity="10"/>
    <dynamics damping="0.001" friction="0.2"/>
    <parent link="module_5.0"/>
    <child link="spring_5.0"/>
    <origin xyz="0 0 -0.05"/>
    <axis xyz="0 1 0"/>
  </joint>
  <link name="spring_5.0">
    <visual>
      <geometry>
        <cylinder length="0.05" radius=".001"/>
      </geometry>
      <origin rpy="1.57075 0 0" xyz="0 0 0"/>
    </visual>
    <inertial>
      <mass value="0.001"/>
      <inertia ixx="0.0" ixy="0.0" ixz="0.0" iyy="0.0" iyz="0.0" izz="0.0"/>
    </inertial>
  </link>
  <joint name="joint_5.0_4.0" type="revolute">
    <limit effort="1000.0" lower="-1.57075" upper="1.57075" velocity="10"/>
    <!-- <dynamics damping="${damping}" friction="${friction}" /> -->
    <parent link="spring_5.0"/>
    <child link="module_4.0"/>
    <origin rpy="0 0 0" xyz="0 0 0"/>
    <axis xyz="0 1 0"/>
  </joint>
  <link name="module_4.0">
    <collision>
      <geometry>
        <cylinder length="0.05" radius="0.025"/>
      </geometry>
      <origin rpy="0 0 0" xyz="0 0 -0.025"/>
    </collision>
    <visual>
      <geometry>
        <cylinder length="0.05" radius="0.025"/>
      </geometry>
      <origin rpy="0 0 0" xyz="0 0 -0.025"/>
    </visual>
    <inertial>
      <origin rpy="0 0 0" xyz="0 0 -0.025"/>
      <mass value="0.159"/>
      <inertia ixx="0.00006" ixy="0" ixz="0" iyy="0.00006" iyz="0" izz="0.00006"/>
    </inertial>
  </link>
  <!-- Springy joint -->
  <joint name="joint_4.0_m" type="revolute">
    <limit effort="1000.0" lower="-1.57075" upper="1.57075" velocity="10"/>
    <dynamics damping="0.001" friction="0.2"/>
    <parent link="module_4.0"/>
    <child link="spring_4.0"/>
    <origin xyz="0 0 -0.05"/>
    <axis xyz="1 0 0"/>
  </joint>
  <link name="spring_4.0">
    <visual>
      <geometry>
        <cylinder length="0.05" radius=".001"/>
      </geometry>
      <origin rpy="1.57075 0 0" xyz="0 0 0"/>
    </visual>
    <inertial>
      <mass value="0.001"/>
      <inertia ixx="0.0" ixy="0.0" ixz="0.0" iyy="0.0" iyz="0.0" izz="0.0"/>
    </inertial>
  </link>
  <joint name="joint_4.0_3.0" type="revolute">
    <limit effort="1000.0" lower="-1.57075" upper="1.57075" velocity="10"/>
    <!-- <dynamics damping="${damping}" friction="${friction}" /> -->
    <parent link="spring_4.0"/>
    <child link="module_3.0"/>
    <origin rpy="0 0 0" xyz="0 0 0"/>
    <axis xyz="1 0 0"/>
  </joint>
  <link name="module_3.0">
    <collision>
      <geometry>
        <cylinder length="0.05" radius="0.025"/>
      </geometry>
      <origin rpy="0 0 0" xyz="0 0 -0.025"/>
    </collision>
    <visual>
      <geometry>
        <cylinder length="0.05" radius="0.025"/>
      </geometry>
      <origin rpy="0 0 0" xyz="0 0 -0.025"/>
    </visual>
    <inertial>
      <origin rpy="0 0 0" xyz="0 0 -0.025"/>
      <mass value="0.159"/>
      <inertia ixx="0.00006" ixy="0" ixz="0" iyy="0.00006" iyz="0" izz="0.00006"/>
    </inertial>
  </link>
  <!-- Springy joint -->
  <joint name="joint_3.0_m" type="revolute">
    <limit effort="1000.0" lower="-1.57075" upper="1.57075" velocity="10"/>
    <dynamics damping="0.001" friction="0.2"/>
    <parent link="module_3.0"/>
    <child link="spring_3.0"/>
    <origin xyz="0 0 -0.05"/>
    <axis xyz="0 1 0"/>
  </joint>
  <link name="spring_3.0">
    <visual>
      <geometry>
        <cylinder length="0.05" radius=".001"/>
      </geometry>
      <origin rpy="1.57075 0 0" xyz="0 0 0"/>
    </visual>
    <inertial>
      <mass value="0.001"/>
      <inertia ixx="0.0" ixy="0.0" ixz="0.0" iyy="0.0" iyz="0.0" izz="0.0"/>
    </inertial>
  </link>
  <joint name="joint_3.0_2.0" type="revolute">
    <limit effort="1000.0" lower="-1.57075" upper="1.57075" velocity="10"/>
    <!-- <dynamics damping="${damping}" friction="${friction}" /> -->
    <parent link="spring_3.0"/>
    <child link="module_2.0"/>
    <origin rpy="0 0 0" xyz="0 0 0"/>
    <axis xyz="0 1 0"/>
  </joint>
  <link name="module_2.0">
    <collision>
      <geometry>
        <cylinder length="0.05" radius="0.025"/>
      </geometry>
      <origin rpy="0 0 0" xyz="0 0 -0.025"/>
    </collision>
    <visual>
      <geometry>
        <cylinder length="0.05" radius="0.025"/>
      </geometry>
      <origin rpy="0 0 0" xyz="0 0 -0.025"/>
    </visual>
    <inertial>
      <origin rpy="0 0 0" xyz="0 0 -0.025"/>
      <mass value="0.159"/>
      <inertia ixx="0.00006" ixy="0" ixz="0" iyy="0.00006" iyz="0" izz="0.00006"/>
    </inertial>
  </link>
  <!-- Springy joint -->
  <joint name="joint_2.0_m" type="revolute">
    <limit effort="1000.0" lower="-1.57075" upper="1.57075" velocity="10"/>
    <dynamics damping="0.001" friction="0.2"/>
    <parent link="module_2.0"/>
    <child link="spring_2.0"/>
    <origin xyz="0 0 -0.05"/>
    <axis xyz="1 0 0"/>
  </joint>
  <link name="spring_2.0">
    <visual>
      <geometry>
        <cylinder length="0.05" radius=".001"/>
      </geometry>
      <origin rpy="1.57075 0 0" xyz="0 0 0"/>
    </visual>
    <inertial>
      <mass value="0.001"/>
      <inertia ixx="0.0" ixy="0.0" ixz="0.0" iyy="0.0" iyz="0.0" izz="0.0"/>
    </inertial>
  </link>
  <joint name="joint_2.0_1.0" type="revolute">
    <limit effort="1000.0" lower="-1.57075" upper="1.57075" velocity="10"/>
    <!-- <dynamics damping="${damping}" friction="${friction}" /> -->
    <parent link="spring_2.0"/>
    <child link="module_1.0"/>
    <origin rpy="0 0 0" xyz="0 0 0"/>
    <axis xyz="1 0 0"/>
  </joint>
  <link name="module_1.0">
    <collision>
      <geometry>
        <cylinder length="0.05" radius="0.025"/>
      </geometry>
      <origin rpy="0 0 0" xyz="0 0 -0.025"/>
    </collision>
    <visual>
      <geometry>
        <cylinder length="0.05" radius="0.025"/>
      </geometry>
      <origin rpy="0 0 0" xyz="0 0 -0.025"/>
    </visual>
    <inertial>
      <origin rpy="0 0 0" xyz="0 0 -0.025"/>
      <mass value="0.159"/>
      <inertia ixx="0.00006" ixy="0" ixz="0" iyy="0.00006" iyz="0" izz="0.00006"/>
    </inertial>
  </link>
  <!-- Springy joint -->
  <joint name="joint_1.0_m" type="revolute">
    <limit effort="1000.0" lower="-1.57075" upper="1.57075" velocity="10"/>
    <dynamics damping="0.001" friction="0.2"/>
    <parent link="module_1.0"/>
    <child link="spring_1.0"/>
    <origin xyz="0 0 -0.05"/>
    <axis xyz="0 1 0"/>
  </joint>
  <link name="spring_1.0">
    <visual>
      <geometry>
        <cylinder length="0.05" radius=".001"/>
      </geometry>
      <origin rpy="1.57075 0 0" xyz="0 0 0"/>
    </visual>
    <inertial>
      <mass value="0.001"/>
      <inertia ixx="0.0" ixy="0.0" ixz="0.0" iyy="0.0" iyz="0.0" izz="0.0"/>
    </inertial>
  </link>
  <joint name="joint_1.0_0.0" type="revolute">
    <limit effort="1000.0" lower="-1.57075" upper="1.57075" velocity="10"/>
    <!-- <dynamics damping="${damping}" friction="${friction}" /> -->
    <parent link="spring_1.0"/>
    <child link="module_0.0"/>
    <origin rpy="0 0 0" xyz="0 0 0"/>
    <axis xyz="0 1 0"/>
  </joint>
  <link name="module_0.0">
    <collision>
      <geometry>
        <cylinder length="0.05" radius="0.025"/>
      </geometry>
      <origin rpy="0 0 0" xyz="0 0 -0.025"/>
    </collision>
    <visual>
      <geometry>
        <cylinder length="0.05" radius="0.025"/>
      </geometry>
      <origin rpy="0 0 0" xyz="0 0 -0.025"/>
    </visual>
    <inertial>
      <origin rpy="0 0 0" xyz="0 0 -0.025"/>
      <mass value="0.159"/>
      <inertia ixx="0.00006" ixy="0" ixz="0" iyy="0.00006" iyz="0" izz="0.00006"/>
    </inertial>
  </link>
  <!-- Springy joint -->
  <joint name="joint_0.0_m" type="revolute">
    <limit effort="1000.0" lower="-1.57075" upper="1.57075" velocity="10"/>
    <dynamics damping="0.001" friction="0.2"/>
    <parent link="module_0.0"/>
    <child link="spring_0.0"/>
    <origin xyz="0 0 -0.05"/>
    <axis xyz="1 0 0"/>
  </joint>
  <link name="spring_0.0">
    <visual>
      <geometry>
        <cylinder length="0.05" radius=".001"/>
      </geometry>
      <origin rpy="1.57075 0 0" xyz="0 0 0"/>
    </visual>
    <inertial>
      <mass value="0.001"/>
      <inertia ixx="0.0" ixy="0.0" ixz="0.0" iyy="0.0" iyz="0.0" izz="0.0"/>
    </inertial>
  </link>
  <joint name="joint_0.0_-1.0" type="revolute">
    <limit effort="1000.0" lower="-1.57075" upper="1.57075" velocity="10"/>
    <!-- <dynamics damping="${damping}" friction="${friction}" /> -->
    <parent link="spring_0.0"/>
    <child link="module_-1.0"/>
    <origin rpy="0 0 0" xyz="0 0 0"/>
    <axis xyz="1 0 0"/>
  </joint>
  <link name="module_-1.0">
    <collision>
      <geometry>
        <cylinder length="0.05" radius="0.025"/>
      </geometry>
      <origin rpy="0 0 0" xyz="0 0 -0.025"/>
    </collision>
    <visual>
      <geometry>
        <cylinder length="0.05" radius="0.025"/>
      </geometry>
      <origin rpy="0 0 0" xyz="0 0 -0.025"/>
    </visual>
    <inertial>
      <origin rpy="0 0 0" xyz="0 0 -0.025"/>
      <mass value="0.159"/>
      <inertia ixx="0.00006" ixy="0" ixz="0" iyy="0.00006" iyz="0" izz="0.00006"/>
    </inertial>
  </link>
</robot>

